Workbook

Sheet KPI Summary
A1: Bank Customer Churn & Loan Portfolio - KPI Summary
A2: Every number below is a live formula on the Customers and Loans sheets. Loan data is simulated.
A4: 1. Customer KPIs
A5: Total customers | B5: =COUNTA(Customers!$A$2:$A$10001) -> 10000
A6: Churned customers | B6: =SUM(Customers!$L$2:$L$10001) -> 2037
A7: Churn rate | B7: =B6/B5 -> 0.2037
A8: Average balance | B8: =AVERAGE(Customers!$G$2:$G$10001) -> 76485.889
A9: Average credit score | B9: =AVERAGE(Customers!$B$2:$B$10001) -> 650.5288
A10: Average age | B10: =AVERAGE(Customers!$E$2:$E$10001) -> 38.9218
A12: 2. Churn by country
A13: Country | B13: Total | C13: Events | D13: Rate
A14: France | B14: =COUNTIF(Customers!$C$2:$C$10001,$A14) -> 5014 | C14: =COUNTIFS(Customers!$C$2:$C$10001,$A14,Customers!$L$2:$L$10001,1) -> 810 | D14: =IF(B14=0,0,C14/B14) -> 0.16154767
A15: Germany | B15: =COUNTIF(Customers!$C$2:$C$10001,$A15) -> 2509 | C15: =COUNTIFS(Customers!$C$2:$C$10001,$A15,Customers!$L$2:$L$10001,1) -> 814 | D15: =IF(B15=0,0,C15/B15) -> 0.32443204
A16: Spain | B16: =COUNTIF(Customers!$C$2:$C$10001,$A16) -> 2477 | C16: =COUNTIFS(Customers!$C$2:$C$10001,$A16,Customers!$L$2:$L$10001,1) -> 413 | D16: =IF(B16=0,0,C16/B16) -> 0.16673395
A18: 3. Churn by age group
A19: Age group | B19: Total | C19: Events | D19: Rate
A20: 18-29 | B20: =COUNTIF(Customers!$M$2:$M$10001,$A20) -> 1641 | C20: =COUNTIFS(Customers!$M$2:$M$10001,$A20,Customers!$L$2:$L$10001,1) -> 124 | D20: =IF(B20=0,0,C20/B20) -> 0.075563681
A21: 30-39 | B21: =COUNTIF(Customers!$M$2:$M$10001,$A21) -> 4346 | C21: =COUNTIFS(Customers!$M$2:$M$10001,$A21,Customers!$L$2:$L$10001,1) -> 473 | D21: =IF(B21=0,0,C21/B21) -> 0.10883571
A22: 40-49 | B22: =COUNTIF(Customers!$M$2:$M$10001,$A22) -> 2618 | C22: =COUNTIFS(Customers!$M$2:$M$10001,$A22,Customers!$L$2:$L$10001,1) -> 806 | D22: =IF(B22=0,0,C22/B22) -> 0.3078686
A23: 50-59 | B23: =COUNTIF(Customers!$M$2:$M$10001,$A23) -> 869 | C23: =COUNTIFS(Customers!$M$2:$M$10001,$A23,Customers!$L$2:$L$10001,1) -> 487 | D23: =IF(B23=0,0,C23/B23) -> 0.56041427
A24: 60+ | B24: =COUNTIF(Customers!$M$2:$M$10001,$A24) -> 526 | C24: =COUNTIFS(Customers!$M$2:$M$10001,$A24,Customers!$L$2:$L$10001,1) -> 147 | D24: =IF(B24=0,0,C24/B24) -> 0.27946768
A26: 4. Churn by number of products
A27: Products | B27: Total | C27: Events | D27: Rate
A28: 1 | B28: =COUNTIF(Customers!$H$2:$H$10001,$A28) -> 5084 | C28: =COUNTIFS(Customers!$H$2:$H$10001,$A28,Customers!$L$2:$L$10001,1) -> 1409 | D28: =IF(B28=0,0,C28/B28) -> 0.27714398
A29: 2 | B29: =COUNTIF(Customers!$H$2:$H$10001,$A29) -> 4590 | C29: =COUNTIFS(Customers!$H$2:$H$10001,$A29,Customers!$L$2:$L$10001,1) -> 348 | D29: =IF(B29=0,0,C29/B29) -> 0.075816993
A30: 3 | B30: =COUNTIF(Customers!$H$2:$H$10001,$A30) -> 266 | C30: =COUNTIFS(Customers!$H$2:$H$10001,$A30,Customers!$L$2:$L$10001,1) -> 220 | D30: =IF(B30=0,0,C30/B30) -> 0.82706767
A31: 4 | B31: =COUNTIF(Customers!$H$2:$H$10001,$A31) -> 60 | C31: =COUNTIFS(Customers!$H$2:$H$10001,$A31,Customers!$L$2:$L$10001,1) -> 60 | D31: =IF(B31=0,0,C31/B31) -> 1
A33: 5. Churn: active vs inactive members
A34: Member type | B34: Total | C34: Events | D34: Rate
A35: Active member | B35: =COUNTIF(Customers!$J$2:$J$10001,1) -> 5151 | C35: =COUNTIFS(Customers!$J$2:$J$10001,1,Customers!$L$2:$L$10001,1) -> 735 | D35: =IF(B35=0,0,C35/B35) -> 0.14269074
A36: Inactive member | B36: =COUNTIF(Customers!$J$2:$J$10001,0) -> 4849 | C36: =COUNTIFS(Customers!$J$2:$J$10001,0,Customers!$L$2:$L$10001,1) -> 1302 | D36: =IF(B36=0,0,C36/B36) -> 0.26850897
A38: 6. Loan portfolio KPIs (simulated data)
A39: Total loans | B39: =COUNTA(Loans!$A$2:$A$4322) -> 4321
A40: Total loan amount | B40: =SUM(Loans!$D$2:$D$4322) -> 776401300
A41: Average interest rate (%) | B41: =AVERAGE(Loans!$E$2:$E$4322) -> 9.0570771
A42: Defaulted loans | B42: =COUNTIF(Loans!$H$2:$H$4322,"Default") -> 424
A43: Default rate | B43: =B42/B39 -> 0.098125434
A44: Defaulted amount | B44: =SUMIF(Loans!$H$2:$H$4322,"Default",Loans!$D$2:$D$4322) -> 110199500
A46: 7. Default rate by loan type
A47: Loan type | B47: Total | C47: Events | D47: Rate
...

Sheet Pivot_Churn_Geo
A3: Average of exited | B3: Column Labels
A4: Row Labels | B4: Female | C4: Male | D4: Grand Total
A5: France | B5: 0.2034498 | C5: 0.12713404 | D5: 0.16154767
A6: Germany | B6: 0.37552389 | C6: 0.2781155 | D6: 0.32443204
A7: Spain | B7: 0.21212121 | C7: 0.13112392 | D7: 0.16673395
A8: Grand Total | B8: 0.25071539 | C8: 0.16455928 | D8: 0.2037

Sheet Pivot_Churn_Age
A3: Row Labels | B3: Average of exited
A4: 18-29 | B4: 0.075563681
A5: 30-39 | B5: 0.10883571
A6: 40-49 | B6: 0.3078686
A7: 50-59 | B7: 0.56041427
A8: 60+ | B8: 0.27946768
A9: Grand Total | B9: 0.2037

Sheet Customers
A1: customer_id | B1: credit_score | C1: geography | D1: gender | E1: age | F1: tenure | G1: balance | H1: num_of_products | I1: has_cr_card | J1: is_active_member | K1: estimated_salary | L1: exited | M1: age_group | N1: credit_score_band | O1: balance_segment | P1: tenure_group | Q1: churn_status
A2: 15634602 | B2: 619 | C2: France | D2: Female | E2: 42 | F2: 2 | G2: 0 | H2: 1 | I2: 1 | J2: 1 | K2: 101348.88 | L2: 1 | M2: 40-49 | N2: 2. Fair | O2: 1. Zero | P2: 0-2 yrs | Q2: Churned
A3: 15647311 | B3: 608 | C3: Spain | D3: Female | E3: 41 | F3: 1 | G3: 83807.86 | H3: 1 | I3: 0 | J3: 1 | K3: 112542.58 | L3: 0 | M3: 40-49 | N3: 2. Fair | O3: 2. Up to 100K | P3: 0-2 yrs | Q3: Retained
A4: 15619304 | B4: 502 | C4: France | D4: Female | E4: 42 | F4: 8 | G4: 159660.8 | H4: 3 | I4: 1 | J4: 0 | K4: 113931.57 | L4: 1 | M4: 40-49 | N4: 1. Poor | O4: 4. Above 150K | P4: 6-8 yrs | Q4: Churned
A5: 15701354 | B5: 699 | C5: France | D5: Female | E5: 39 | F5: 1 | G5: 0 | H5: 2 | I5: 0 | J5: 0 | K5: 93826.63 | L5: 0 | M5: 30-39 | N5: 3. Good | O5: 1. Zero | P5: 0-2 yrs | Q5: Retained
A6: 15737888 | B6: 850 | C6: Spain | D6: Female | E6: 43 | F6: 2 | G6: 125510.82 | H6: 1 | I6: 1 | J6: 1 | K6: 79084.1 | L6: 0 | M6: 40-49 | N6: 5. Excellent | O6: 3. 100K-150K | P6: 0-2 yrs | Q6: Retained
A7: 15574012 | B7: 645 | C7: Spain | D7: Male | E7: 44 | F7: 8 | G7: 113755.78 | H7: 2 | I7: 1 | J7: 0 | K7: 149756.71 | L7: 1 | M7: 40-49 | N7: 2. Fair | O7: 3. 100K-150K | P7: 6-8 yrs | Q7: Churned
A8: 15592531 | B8: 822 | C8: France | D8: Male | E8: 50 | F8: 7 | G8: 0 | H8: 2 | I8: 1 | J8: 1 | K8: 10062.8 | L8: 0 | M8: 50-59 | N8: 5. Excellent | O8: 1. Zero | P8: 6-8 yrs | Q8: Retained
A9: 15656148 | B9: 376 | C9: Germany | D9: Female | E9: 29 | F9: 4 | G9: 115046.74 | H9: 4 | I9: 1 | J9: 0 | K9: 119346.88 | L9: 1 | M9: 18-29 | N9: 1. Poor | O9: 3. 100K-150K | P9: 3-5 yrs | Q9: Churned
A10: 15792365 | B10: 501 | C10: France | D10: Male | E10: 44 | F10: 4 | G10: 142051.07 | H10: 2 | I10: 0 | J10: 1 | K10: 74940.5 | L10: 0 | M10: 40-49 | N10: 1. Poor | O10: 3. 100K-150K | P10: 3-5 yrs | Q10: Retained
A11: 15592389 | B11: 684 | C11: France | D11: Male | E11: 27 | F11: 2 | G11: 134603.88 | H11: 1 | I11: 1 | J11: 1 | K11: 71725.73 | L11: 0 | M11: 18-29 | N11: 3. Good | O11: 3. 100K-150K | P11: 0-2 yrs | Q11: Retained
A12: 15767821 | B12: 528 | C12: France | D12: Male | E12: 31 | F12: 6 | G12: 102016.72 | H12: 2 | I12: 0 | J12: 0 | K12: 80181.12 | L12: 0 | M12: 30-39 | N12: 1. Poor | O12: 3. 100K-150K | P12: 6-8 yrs | Q12: Retained
A13: 15737173 | B13: 497 | C13: Spain | D13: Male | E13: 24 | F13: 3 | G13: 0 | H13: 2 | I13: 1 | J13: 0 | K13: 76390.01 | L13: 0 | M13: 18-29 | N13: 1. Poor | O13: 1. Zero | P13: 3-5 yrs | Q13: Retained
... A10001: 15628319 | B10001: 792 | C10001: France | D10001: Female | E10001: 28 | F10001: 4 | G10001: 130142.79 | H10001: 1 | I10001: 1 | J10001: 0 | K10001: 38190.78 | L10001: 0 | M10001: 18-29 | N10001: 4. Very Good | O10001: 3. 100K-150K | P10001: 3-5 yrs | Q10001: Retained

Sheet Pivot_Loans
A3: Count of loan_id | B3: Column Labels
A4: Row Labels | B4: Active | C4: Closed | D4: Default | E4: Grand Total
A5: Auto | B5: 742 | C5: 263 | D5: 86 | E5: 1091
A6: Business | B6: 415 | C6: 181 | D6: 77 | E6: 673
A7: Education | B7: 382 | C7: 50 | D7: 23 | E7: 455
A8: Home | B8: 681 | D8: 165 | E8: 846
A9: Personal | B9: 667 | C9: 516 | D9: 73 | E9: 1256
A10: Grand Total | B10: 2887 | C10: 1010 | D10: 424 | E10: 4321

Sheet Loans
A1: loan_id | B1: customer_id | C1: loan_type | D1: loan_amount | E1: interest_rate | F1: tenure_months | G1: loan_start_date | H1: loan_status | I1: days_past_due
A2: L00001 | B2: 15720354 | C2: Home | D2: 769600 | E2: 7.36 | F2: 120 | G2: 2021-01-01 | H2: Active | I2: 0
A3: L00002 | B3: 15794870 | C3: Home | D3: 402500 | E3: 4.33 | F3: 180 | G3: 2021-01-01 | H3: Active | I3: 0
A4: L00003 | B4: 15645045 | C4: Business | D4: 458900 | E4: 10.59 | F4: 24 | G4: 2021-01-01 | H4: Closed | I4: 0
A5: L00004 | B5: 15815690 | C5: Auto | D5: 154100 | E5: 8.92 | F5: 72 | G5: 2021-01-02 | H5: Active | I5: 0
A6: L00005 | B6: 15721719 | C6: Personal | D6: 37600 | E6: 10.53 | F6: 36 | G6: 2021-01-02 | H6: Closed | I6: 0
A7: L00006 | B7: 15772618 | C7: Education | D7: 103000 | E7: 6.8 | F7: 36 | G7: 2021-01-02 | H7: Closed | I7: 0
A8: L00007 | B8: 15777784 | C8: Home | D8: 652000 | E8: 5.98 | F8: 180 | G8: 2021-01-02 | H8: Active | I8: 0
A9: L00008 | B9: 15600379 | C9: Home | D9: 333100 | E9: 6.99 | F9: 360 | G9: 2021-01-03 | H9: Default | I9: 234
A10: L00009 | B10: 15738088 | C10: Auto | D10: 39100 | E10: 8.63 | F10: 36 | G10: 2021-01-03 | H10: Closed | I10: 0
A11: L00010 | B11: 15799790 | C11: Personal | D11: 19900 | E11: 11.01 | F11: 36 | G11: 2021-01-03 | H11: Closed | I11: 0
A12: L00011 | B12: 15713479 | C12: Personal | D12: 1000 | E12: 11.66 | F12: 60 | G12: 2021-01-03 | H12: Active | I12: 0
A13: L00012 | B13: 15707602 | C13: Personal | D13: 57200 | E13: 12.51 | F13: 48 | G13: 2021-01-03 | H13: Closed | I13: 0
... A4322: L04321 | B4322: 15697606 | C4322: Business | D4322: 382300 | E4322: 10.44 | F4322: 60 | G4322: 2025-06-30 | H4322: Active | I4322: 0
